[2025-01-01T02:50:03.428+0000] {local_task_job_runner.py:123} INFO - ::group::Pre task execution logs
[2025-01-01T02:50:03.447+0000] {taskinstance.py:2613} INFO - Dependencies all met for dep_context=non-requeueable deps ti=<TaskInstance: etl_reddit_pipeline.s3_upload manual__2025-01-01T02:49:58.261805+00:00 [queued]>
[2025-01-01T02:50:03.455+0000] {taskinstance.py:2613} INFO - Dependencies all met for dep_context=requeueable deps ti=<TaskInstance: etl_reddit_pipeline.s3_upload manual__2025-01-01T02:49:58.261805+00:00 [queued]>
[2025-01-01T02:50:03.456+0000] {taskinstance.py:2866} INFO - Starting attempt 1 of 1
[2025-01-01T02:50:03.468+0000] {taskinstance.py:2889} INFO - Executing <Task(PythonOperator): s3_upload> on 2025-01-01 02:49:58.261805+00:00
[2025-01-01T02:50:03.475+0000] {standard_task_runner.py:72} INFO - Started process 74 to run task
[2025-01-01T02:50:03.479+0000] {standard_task_runner.py:104} INFO - Running: ['airflow', 'tasks', 'run', 'etl_reddit_pipeline', 's3_upload', 'manual__2025-01-01T02:49:58.261805+00:00', '--job-id', '88', '--raw', '--subdir', 'DAGS_FOLDER/reddit_dag.py', '--cfg-path', '/tmp/tmp3errl9yz']
[2025-01-01T02:50:03.482+0000] {standard_task_runner.py:105} INFO - Job 88: Subtask s3_upload
[2025-01-01T02:50:03.533+0000] {task_command.py:467} INFO - Running <TaskInstance: etl_reddit_pipeline.s3_upload manual__2025-01-01T02:49:58.261805+00:00 [running]> on host ce45827b1ff5
[2025-01-01T02:50:03.615+0000] {taskinstance.py:3132} INFO - Exporting env vars: AIRFLOW_CTX_DAG_OWNER='Joseph DiLullo' AIRFLOW_CTX_DAG_ID='etl_reddit_pipeline' AIRFLOW_CTX_TASK_ID='s3_upload' AIRFLOW_CTX_EXECUTION_DATE='2025-01-01T02:49:58.261805+00:00' AIRFLOW_CTX_TRY_NUMBER='1' AIRFLOW_CTX_DAG_RUN_ID='manual__2025-01-01T02:49:58.261805+00:00'
[2025-01-01T02:50:03.617+0000] {taskinstance.py:731} INFO - ::endgroup::
[2025-01-01T02:50:05.870+0000] {logging_mixin.py:190} INFO - The AWS Access Key Id you provided does not exist in our records.
[2025-01-01T02:50:06.041+0000] {taskinstance.py:3311} ERROR - Task failed with exception
Traceback (most recent call last):
  File "/home/airflow/.local/lib/python3.9/site-packages/s3fs/core.py", line 734, in _lsdir
    async for c in self._iterdir(
  File "/home/airflow/.local/lib/python3.9/site-packages/s3fs/core.py", line 784, in _iterdir
    async for i in it:
  File "/home/airflow/.local/lib/python3.9/site-packages/aiobotocore/paginate.py", line 30, in __anext__
    response = await self._make_request(current_kwargs)
  File "/home/airflow/.local/lib/python3.9/site-packages/aiobotocore/client.py", line 412, in _make_api_call
    raise error_class(parsed_response, operation_name)
botocore.exceptions.ClientError: An error occurred (InvalidAccessKeyId) when calling the ListObjectsV2 operation: The AWS Access Key Id you provided does not exist in our records.

The above exception was the direct cause of the following exception:

Traceback (most recent call last):
  File "/home/airflow/.local/lib/python3.9/site-packages/airflow/models/taskinstance.py", line 767, in _execute_task
    result = _execute_callable(context=context, **execute_callable_kwargs)
  File "/home/airflow/.local/lib/python3.9/site-packages/airflow/models/taskinstance.py", line 733, in _execute_callable
    return ExecutionCallableRunner(
  File "/home/airflow/.local/lib/python3.9/site-packages/airflow/utils/operator_helpers.py", line 252, in run
    return self.func(*args, **kwargs)
  File "/home/airflow/.local/lib/python3.9/site-packages/airflow/models/baseoperator.py", line 422, in wrapper
    return func(self, *args, **kwargs)
  File "/home/airflow/.local/lib/python3.9/site-packages/airflow/operators/python.py", line 238, in execute
    return_value = self.execute_callable()
  File "/home/airflow/.local/lib/python3.9/site-packages/airflow/operators/python.py", line 256, in execute_callable
    return runner.run(*self.op_args, **self.op_kwargs)
  File "/home/airflow/.local/lib/python3.9/site-packages/airflow/utils/operator_helpers.py", line 252, in run
    return self.func(*args, **kwargs)
  File "/opt/airflow/pipelines/aws_s3_pipeline.py", line 9, in upload_s3_pipeline
    upload_to_s3(s3, file_path, 'airscholar-reddit-engineering1', file_path.split('/')[-1])
  File "/opt/airflow/etls/aws_etl.py", line 26, in upload_to_s3
    s3.put(file_path, bucket+'/raw/'+ s3_file_name)
  File "/home/airflow/.local/lib/python3.9/site-packages/fsspec/asyn.py", line 118, in wrapper
    return sync(self.loop, func, *args, **kwargs)
  File "/home/airflow/.local/lib/python3.9/site-packages/fsspec/asyn.py", line 103, in sync
    raise return_result
  File "/home/airflow/.local/lib/python3.9/site-packages/fsspec/asyn.py", line 56, in _runner
    result[0] = await coro
  File "/home/airflow/.local/lib/python3.9/site-packages/fsspec/asyn.py", line 565, in _put
    trailing_sep(rpath) or await self._isdir(rpath)
  File "/home/airflow/.local/lib/python3.9/site-packages/s3fs/core.py", line 1535, in _isdir
    return bool(await self._lsdir(path))
  File "/home/airflow/.local/lib/python3.9/site-packages/s3fs/core.py", line 747, in _lsdir
    raise translate_boto_error(e)
PermissionError: The AWS Access Key Id you provided does not exist in our records.
[2025-01-01T02:50:06.063+0000] {taskinstance.py:1225} INFO - Marking task as FAILED. dag_id=etl_reddit_pipeline, task_id=s3_upload, run_id=manual__2025-01-01T02:49:58.261805+00:00, execution_date=20250101T024958, start_date=20250101T025003, end_date=20250101T025006
[2025-01-01T02:50:06.077+0000] {taskinstance.py:340} INFO - ::group::Post task execution logs
[2025-01-01T02:50:06.078+0000] {standard_task_runner.py:124} ERROR - Failed to execute job 88 for task s3_upload (The AWS Access Key Id you provided does not exist in our records.; 74)
Traceback (most recent call last):
  File "/home/airflow/.local/lib/python3.9/site-packages/s3fs/core.py", line 734, in _lsdir
    async for c in self._iterdir(
  File "/home/airflow/.local/lib/python3.9/site-packages/s3fs/core.py", line 784, in _iterdir
    async for i in it:
  File "/home/airflow/.local/lib/python3.9/site-packages/aiobotocore/paginate.py", line 30, in __anext__
    response = await self._make_request(current_kwargs)
  File "/home/airflow/.local/lib/python3.9/site-packages/aiobotocore/client.py", line 412, in _make_api_call
    raise error_class(parsed_response, operation_name)
botocore.exceptions.ClientError: An error occurred (InvalidAccessKeyId) when calling the ListObjectsV2 operation: The AWS Access Key Id you provided does not exist in our records.

The above exception was the direct cause of the following exception:

Traceback (most recent call last):
  File "/home/airflow/.local/lib/python3.9/site-packages/airflow/task/task_runner/standard_task_runner.py", line 117, in _start_by_fork
    ret = args.func(args, dag=self.dag)
  File "/home/airflow/.local/lib/python3.9/site-packages/airflow/cli/cli_config.py", line 49, in command
    return func(*args, **kwargs)
  File "/home/airflow/.local/lib/python3.9/site-packages/airflow/utils/cli.py", line 116, in wrapper
    return f(*args, **kwargs)
  File "/home/airflow/.local/lib/python3.9/site-packages/airflow/cli/commands/task_command.py", line 483, in task_run
    task_return_code = _run_task_by_selected_method(args, _dag, ti)
  File "/home/airflow/.local/lib/python3.9/site-packages/airflow/cli/commands/task_command.py", line 256, in _run_task_by_selected_method
    return _run_raw_task(args, ti)
  File "/home/airflow/.local/lib/python3.9/site-packages/airflow/cli/commands/task_command.py", line 341, in _run_raw_task
    return ti._run_raw_task(
  File "/home/airflow/.local/lib/python3.9/site-packages/airflow/utils/session.py", line 97, in wrapper
    return func(*args, session=session, **kwargs)
  File "/home/airflow/.local/lib/python3.9/site-packages/airflow/models/taskinstance.py", line 3005, in _run_raw_task
    return _run_raw_task(
  File "/home/airflow/.local/lib/python3.9/site-packages/airflow/models/taskinstance.py", line 273, in _run_raw_task
    TaskInstance._execute_task_with_callbacks(
  File "/home/airflow/.local/lib/python3.9/site-packages/airflow/models/taskinstance.py", line 3159, in _execute_task_with_callbacks
    result = self._execute_task(context, task_orig)
  File "/home/airflow/.local/lib/python3.9/site-packages/airflow/models/taskinstance.py", line 3183, in _execute_task
    return _execute_task(self, context, task_orig)
  File "/home/airflow/.local/lib/python3.9/site-packages/airflow/models/taskinstance.py", line 767, in _execute_task
    result = _execute_callable(context=context, **execute_callable_kwargs)
  File "/home/airflow/.local/lib/python3.9/site-packages/airflow/models/taskinstance.py", line 733, in _execute_callable
    return ExecutionCallableRunner(
  File "/home/airflow/.local/lib/python3.9/site-packages/airflow/utils/operator_helpers.py", line 252, in run
    return self.func(*args, **kwargs)
  File "/home/airflow/.local/lib/python3.9/site-packages/airflow/models/baseoperator.py", line 422, in wrapper
    return func(self, *args, **kwargs)
  File "/home/airflow/.local/lib/python3.9/site-packages/airflow/operators/python.py", line 238, in execute
    return_value = self.execute_callable()
  File "/home/airflow/.local/lib/python3.9/site-packages/airflow/operators/python.py", line 256, in execute_callable
    return runner.run(*self.op_args, **self.op_kwargs)
  File "/home/airflow/.local/lib/python3.9/site-packages/airflow/utils/operator_helpers.py", line 252, in run
    return self.func(*args, **kwargs)
  File "/opt/airflow/pipelines/aws_s3_pipeline.py", line 9, in upload_s3_pipeline
    upload_to_s3(s3, file_path, 'airscholar-reddit-engineering1', file_path.split('/')[-1])
  File "/opt/airflow/etls/aws_etl.py", line 26, in upload_to_s3
    s3.put(file_path, bucket+'/raw/'+ s3_file_name)
  File "/home/airflow/.local/lib/python3.9/site-packages/fsspec/asyn.py", line 118, in wrapper
    return sync(self.loop, func, *args, **kwargs)
  File "/home/airflow/.local/lib/python3.9/site-packages/fsspec/asyn.py", line 103, in sync
    raise return_result
  File "/home/airflow/.local/lib/python3.9/site-packages/fsspec/asyn.py", line 56, in _runner
    result[0] = await coro
  File "/home/airflow/.local/lib/python3.9/site-packages/fsspec/asyn.py", line 565, in _put
    trailing_sep(rpath) or await self._isdir(rpath)
  File "/home/airflow/.local/lib/python3.9/site-packages/s3fs/core.py", line 1535, in _isdir
    return bool(await self._lsdir(path))
  File "/home/airflow/.local/lib/python3.9/site-packages/s3fs/core.py", line 747, in _lsdir
    raise translate_boto_error(e)
PermissionError: The AWS Access Key Id you provided does not exist in our records.
[2025-01-01T02:50:06.119+0000] {local_task_job_runner.py:266} INFO - Task exited with return code 1
[2025-01-01T02:50:06.138+0000] {taskinstance.py:3895} INFO - 0 downstream tasks scheduled from follow-on schedule check
[2025-01-01T02:50:06.140+0000] {local_task_job_runner.py:245} INFO - ::endgroup::
