[2024-12-28T00:11:56.411+0000] {local_task_job_runner.py:123} INFO - ::group::Pre task execution logs
[2024-12-28T00:11:56.427+0000] {taskinstance.py:2613} INFO - Dependencies all met for dep_context=non-requeueable deps ti=<TaskInstance: etl_reddit_pipeline.reddit_extraction scheduled__2024-12-27T00:00:00+00:00 [queued]>
[2024-12-28T00:11:56.434+0000] {taskinstance.py:2613} INFO - Dependencies all met for dep_context=requeueable deps ti=<TaskInstance: etl_reddit_pipeline.reddit_extraction scheduled__2024-12-27T00:00:00+00:00 [queued]>
[2024-12-28T00:11:56.435+0000] {taskinstance.py:2866} INFO - Starting attempt 1 of 1
[2024-12-28T00:11:56.446+0000] {taskinstance.py:2889} INFO - Executing <Task(PythonOperator): reddit_extraction> on 2024-12-27 00:00:00+00:00
[2024-12-28T00:11:56.452+0000] {standard_task_runner.py:72} INFO - Started process 143 to run task
[2024-12-28T00:11:56.457+0000] {standard_task_runner.py:104} INFO - Running: ['airflow', 'tasks', 'run', 'etl_reddit_pipeline', 'reddit_extraction', 'scheduled__2024-12-27T00:00:00+00:00', '--job-id', '48', '--raw', '--subdir', 'DAGS_FOLDER/reddit_dag.py', '--cfg-path', '/tmp/tmp27ms1hex']
[2024-12-28T00:11:56.459+0000] {standard_task_runner.py:105} INFO - Job 48: Subtask reddit_extraction
[2024-12-28T00:11:56.516+0000] {task_command.py:467} INFO - Running <TaskInstance: etl_reddit_pipeline.reddit_extraction scheduled__2024-12-27T00:00:00+00:00 [running]> on host 54e9c9696444
[2024-12-28T00:11:56.592+0000] {taskinstance.py:3132} INFO - Exporting env vars: AIRFLOW_CTX_DAG_OWNER='Joseph DiLullo' AIRFLOW_CTX_DAG_ID='etl_reddit_pipeline' AIRFLOW_CTX_TASK_ID='reddit_extraction' AIRFLOW_CTX_EXECUTION_DATE='2024-12-27T00:00:00+00:00' AIRFLOW_CTX_TRY_NUMBER='1' AIRFLOW_CTX_DAG_RUN_ID='scheduled__2024-12-27T00:00:00+00:00'
[2024-12-28T00:11:56.593+0000] {taskinstance.py:731} INFO - ::endgroup::
[2024-12-28T00:11:56.872+0000] {logging_mixin.py:190} INFO - We are connected to Reddit
[2024-12-28T00:11:56.873+0000] {taskinstance.py:3311} ERROR - Task failed with exception
Traceback (most recent call last):
  File "/home/airflow/.local/lib/python3.9/site-packages/airflow/models/taskinstance.py", line 767, in _execute_task
    result = _execute_callable(context=context, **execute_callable_kwargs)
  File "/home/airflow/.local/lib/python3.9/site-packages/airflow/models/taskinstance.py", line 733, in _execute_callable
    return ExecutionCallableRunner(
  File "/home/airflow/.local/lib/python3.9/site-packages/airflow/utils/operator_helpers.py", line 252, in run
    return self.func(*args, **kwargs)
  File "/home/airflow/.local/lib/python3.9/site-packages/airflow/models/baseoperator.py", line 422, in wrapper
    return func(self, *args, **kwargs)
  File "/home/airflow/.local/lib/python3.9/site-packages/airflow/operators/python.py", line 238, in execute
    return_value = self.execute_callable()
  File "/home/airflow/.local/lib/python3.9/site-packages/airflow/operators/python.py", line 256, in execute_callable
    return runner.run(*self.op_args, **self.op_kwargs)
  File "/home/airflow/.local/lib/python3.9/site-packages/airflow/utils/operator_helpers.py", line 252, in run
    return self.func(*args, **kwargs)
  File "/opt/airflow/pipelines/reddit_pipeline.py", line 8, in reddit_pipeline
    posts = extract_posts(instance, subreddit, time_filter, limit)
  File "/opt/airflow/etls/reddit_etl.py", line 22, in extract_posts
    posts = subreddit.new(time_filter=time_filter, limit=limit)
  File "/home/airflow/.local/lib/python3.9/site-packages/praw/models/listing/mixins/base.py", line 119, in new
    return ListingGenerator(self._reddit, url, **generator_kwargs)
TypeError: __init__() got an unexpected keyword argument 'time_filter'
[2024-12-28T00:11:56.884+0000] {taskinstance.py:1225} INFO - Marking task as FAILED. dag_id=etl_reddit_pipeline, task_id=reddit_extraction, run_id=scheduled__2024-12-27T00:00:00+00:00, execution_date=20241227T000000, start_date=20241228T001156, end_date=20241228T001156
[2024-12-28T00:11:56.899+0000] {taskinstance.py:340} INFO - ::group::Post task execution logs
[2024-12-28T00:11:56.900+0000] {standard_task_runner.py:124} ERROR - Failed to execute job 48 for task reddit_extraction (__init__() got an unexpected keyword argument 'time_filter'; 143)
Traceback (most recent call last):
  File "/home/airflow/.local/lib/python3.9/site-packages/airflow/task/task_runner/standard_task_runner.py", line 117, in _start_by_fork
    ret = args.func(args, dag=self.dag)
  File "/home/airflow/.local/lib/python3.9/site-packages/airflow/cli/cli_config.py", line 49, in command
    return func(*args, **kwargs)
  File "/home/airflow/.local/lib/python3.9/site-packages/airflow/utils/cli.py", line 116, in wrapper
    return f(*args, **kwargs)
  File "/home/airflow/.local/lib/python3.9/site-packages/airflow/cli/commands/task_command.py", line 483, in task_run
    task_return_code = _run_task_by_selected_method(args, _dag, ti)
  File "/home/airflow/.local/lib/python3.9/site-packages/airflow/cli/commands/task_command.py", line 256, in _run_task_by_selected_method
    return _run_raw_task(args, ti)
  File "/home/airflow/.local/lib/python3.9/site-packages/airflow/cli/commands/task_command.py", line 341, in _run_raw_task
    return ti._run_raw_task(
  File "/home/airflow/.local/lib/python3.9/site-packages/airflow/utils/session.py", line 97, in wrapper
    return func(*args, session=session, **kwargs)
  File "/home/airflow/.local/lib/python3.9/site-packages/airflow/models/taskinstance.py", line 3005, in _run_raw_task
    return _run_raw_task(
  File "/home/airflow/.local/lib/python3.9/site-packages/airflow/models/taskinstance.py", line 273, in _run_raw_task
    TaskInstance._execute_task_with_callbacks(
  File "/home/airflow/.local/lib/python3.9/site-packages/airflow/models/taskinstance.py", line 3159, in _execute_task_with_callbacks
    result = self._execute_task(context, task_orig)
  File "/home/airflow/.local/lib/python3.9/site-packages/airflow/models/taskinstance.py", line 3183, in _execute_task
    return _execute_task(self, context, task_orig)
  File "/home/airflow/.local/lib/python3.9/site-packages/airflow/models/taskinstance.py", line 767, in _execute_task
    result = _execute_callable(context=context, **execute_callable_kwargs)
  File "/home/airflow/.local/lib/python3.9/site-packages/airflow/models/taskinstance.py", line 733, in _execute_callable
    return ExecutionCallableRunner(
  File "/home/airflow/.local/lib/python3.9/site-packages/airflow/utils/operator_helpers.py", line 252, in run
    return self.func(*args, **kwargs)
  File "/home/airflow/.local/lib/python3.9/site-packages/airflow/models/baseoperator.py", line 422, in wrapper
    return func(self, *args, **kwargs)
  File "/home/airflow/.local/lib/python3.9/site-packages/airflow/operators/python.py", line 238, in execute
    return_value = self.execute_callable()
  File "/home/airflow/.local/lib/python3.9/site-packages/airflow/operators/python.py", line 256, in execute_callable
    return runner.run(*self.op_args, **self.op_kwargs)
  File "/home/airflow/.local/lib/python3.9/site-packages/airflow/utils/operator_helpers.py", line 252, in run
    return self.func(*args, **kwargs)
  File "/opt/airflow/pipelines/reddit_pipeline.py", line 8, in reddit_pipeline
    posts = extract_posts(instance, subreddit, time_filter, limit)
  File "/opt/airflow/etls/reddit_etl.py", line 22, in extract_posts
    posts = subreddit.new(time_filter=time_filter, limit=limit)
  File "/home/airflow/.local/lib/python3.9/site-packages/praw/models/listing/mixins/base.py", line 119, in new
    return ListingGenerator(self._reddit, url, **generator_kwargs)
TypeError: __init__() got an unexpected keyword argument 'time_filter'
[2024-12-28T00:11:56.924+0000] {local_task_job_runner.py:266} INFO - Task exited with return code 1
[2024-12-28T00:11:56.938+0000] {taskinstance.py:3895} INFO - 0 downstream tasks scheduled from follow-on schedule check
[2024-12-28T00:11:56.940+0000] {local_task_job_runner.py:245} INFO - ::endgroup::
